<?xml version="1.0"?>
<robot name="my_robot" xmlns:xacro="http://www.ros.org/wiki/xacro">

  <!-- PROPERTIES -->
  <xacro:property name="chassis_length" value="0.4"/>
  <xacro:property name="chassis_width"  value="0.3"/>
  <xacro:property name="chassis_height" value="0.1"/>
  <xacro:property name="wheel_radius"   value="0.05"/>
  <xacro:property name="wheel_width"    value="0.04"/>

  <!-- WHEEL MACRO -->
  <xacro:macro name="wheel" params="name x y">
    <link name="${name}">
      <visual>
        <geometry>
          <cylinder radius="${wheel_radius}" length="${wheel_width}"/>
        </geometry>
        <material name="black">
          <color rgba="0 0 0 1"/>
        </material>
      </visual>
      <collision>
        <geometry>
          <cylinder radius="${wheel_radius}" length="${wheel_width}"/>
        </geometry>
      </collision>
      <inertial>
        <mass value="0.5"/>
        <inertia ixx="0.001" ixy="0" ixz="0"
                 iyy="0.001" iyz="0" izz="0.001"/>
      </inertial>
    </link>
    <joint name="${name}_joint" type="continuous">
      <parent link="chassis"/>
      <child  link="${name}"/>
      <origin xyz="${x} ${y} 0" rpy="1.5708 0 0"/>
      <axis xyz="0 0 1"/>
    </joint>
  </xacro:macro>

  <!-- BASE LINK -->
  <link name="base_link"/>
  <joint name="base_joint" type="fixed">
    <parent link="base_link"/>
    <child  link="chassis"/>
    <origin xyz="0 0 0.1"/>
  </joint>

  <!-- CHASSIS -->
  <link name="chassis">
    <visual>
      <geometry>
        <box size="${chassis_length} ${chassis_width} ${chassis_height}"/>
      </geometry>
      <material name="blue">
        <color rgba="0 0 1 1"/>
      </material>
    </visual>
    <collision>
      <geometry>
        <box size="${chassis_length} ${chassis_width} ${chassis_height}"/>
      </geometry>
    </collision>
    <inertial>
      <mass value="2.0"/>
      <inertia ixx="0.01" ixy="0" ixz="0"
               iyy="0.01" iyz="0" izz="0.01"/>
    </inertial>
  </link>

  <!-- 4 WHEELS -->
  <xacro:wheel name="front_left_wheel"  x=" 0.15" y=" 0.17"/>
  <xacro:wheel name="front_right_wheel" x=" 0.15" y="-0.17"/>
  <xacro:wheel name="rear_left_wheel"   x="-0.15" y=" 0.17"/>
  <xacro:wheel name="rear_right_wheel"  x="-0.15" y="-0.17"/>

  <!-- LIDAR -->
  <link name="lidar_link">
    <visual>
      <geometry>
        <cylinder radius="0.05" length="0.04"/>
      </geometry>
      <material name="black">
        <color rgba="0 0 0 1"/>
      </material>
    </visual>
    <collision>
      <geometry>
        <cylinder radius="0.05" length="0.04"/>
      </geometry>
    </collision>
    <inertial>
      <mass value="0.1"/>
      <inertia ixx="0.001" ixy="0" ixz="0"
               iyy="0.001" iyz="0" izz="0.001"/>
    </inertial>
  </link>
  <joint name="lidar_joint" type="fixed">
    <parent link="chassis"/>
    <child link="lidar_link"/>
    <origin xyz="0.1 0 0.07" rpy="0 0 0"/>
  </joint>

  <!-- IMU -->
  <link name="imu_link">
    <visual>
      <geometry>
        <box size="0.03 0.03 0.01"/>
      </geometry>
      <material name="green">
        <color rgba="0 1 0 1"/>
      </material>
    </visual>
    <inertial>
      <mass value="0.01"/>
      <inertia ixx="0.0001" ixy="0" ixz="0"
               iyy="0.0001" iyz="0" izz="0.0001"/>
    </inertial>
  </link>
  <joint name="imu_joint" type="fixed">
    <parent link="chassis"/>
    <child link="imu_link"/>
    <origin xyz="0 0 0.06" rpy="0 0 0"/>
  </joint>

  <!-- ARM BASE -->
  <link name="arm_base">
    <visual>
      <geometry>
        <box size="0.05 0.05 0.1"/>
      </geometry>
      <material name="orange">
        <color rgba="1 0.5 0 1"/>
      </material>
    </visual>
    <collision>
      <geometry>
        <box size="0.05 0.05 0.1"/>
      </geometry>
    </collision>
    <inertial>
      <mass value="0.3"/>
      <inertia ixx="0.001" ixy="0" ixz="0"
               iyy="0.001" iyz="0" izz="0.001"/>
    </inertial>
  </link>
  <joint name="arm_joint" type="revolute">
    <parent link="chassis"/>
    <child link="arm_base"/>
    <origin xyz="-0.1 0 0.05" rpy="0 0 0"/>
    <axis xyz="0 1 0"/>
    <limit lower="-1.57" upper="1.57" effort="10" velocity="1"/>
  </joint>

  <!-- CAMERA -->
  <link name="camera_link">
    <visual>
      <geometry>
        <box size="0.03 0.06 0.03"/>
      </geometry>
      <material name="red">
        <color rgba="1 0 0 1"/>
      </material>
    </visual>
    <collision>
      <geometry>
        <box size="0.03 0.06 0.03"/>
      </geometry>
    </collision>
    <inertial>
      <mass value="0.05"/>
      <inertia ixx="0.0001" ixy="0" ixz="0"
               iyy="0.0001" iyz="0" izz="0.0001"/>
    </inertial>
  </link>
  <joint name="camera_joint" type="fixed">
    <parent link="arm_base"/>
    <child link="camera_link"/>
    <origin xyz="0 0 0.065" rpy="0 0 0"/>
  </joint>

  <!-- CAMERA OPTICAL FRAME -->
  <link name="camera_optical_frame"/>
  <joint name="camera_optical_joint" type="fixed">
    <parent link="camera_link"/>
    <child link="camera_optical_frame"/>
    <origin xyz="0 0 0" rpy="-1.5708 0 -1.5708"/>
  </joint>

  <!-- GAZEBO PLUGINS -->

  <!-- LiDAR Plugin -->
  <gazebo reference="lidar_link">
    <sensor name="lidar" type="gpu_lidar">
      <pose>0 0 0 0 0 0</pose>
      <update_rate>10</update_rate>
      <lidar>
        <scan>
          <horizontal>
            <samples>360</samples>
            <resolution>1</resolution>
            <min_angle>-3.14</min_angle>
            <max_angle>3.14</max_angle>
          </horizontal>
        </scan>
        <range>
          <min>0.1</min>
          <max>10.0</max>
        </range>
      </lidar>
      <always_on>1</always_on>
      <visualize>true</visualize>
      <topic>/lidar</topic>
    </sensor>
  </gazebo>

  <!-- IMU Plugin -->
  <gazebo reference="imu_link">
    <sensor name="imu" type="imu">
      <always_on>1</always_on>
      <update_rate>100</update_rate>
      <topic>/imu</topic>
      <visualize>true</visualize>
    </sensor>
  </gazebo>

  <!-- Camera Plugin -->
  <gazebo reference="camera_link">
    <sensor name="camera" type="camera">
      <always_on>1</always_on>
      <update_rate>10</update_rate>
      <visualize>true</visualize>
      <topic>camera/image</topic>
      <camera name="camera">
        <horizontal_fov>1.047</horizontal_fov>
        <image>
          <width>320</width>
          <height>240</height>
          <format>R8G8B8</format>
        </image>
        <clip>
          <near>0.1</near>
          <far>100</far>
        </clip>
        <noise>
          <type>gaussian</type>
          <mean>0</mean>
          <stddev>0.007</stddev>
        </noise>
      </camera>
    </sensor>
  </gazebo>
  
</robot>
